Workbook

Sheet Raw_Transcripts
A1: participant_id | B1: start | C1: end | D1: text | E1: speaker | F1: source_type | G1: main_phase | H1: sub_phase | I1: deductive_code | J1: quotes | K1: inductive_codes
A2: 1 | B2: 1029 | C2: 9370 | D2: Ja, dann nochmal danke dir, dass du dir die Zeit genommen hast und die Nutzerstudie dauert | E2: Speaker 2 | G2: General
A3: 1 | B3: 9370 | C3: 16450 | D3: so ungefähr 45 bis 60 Minuten, das Interview wird mit der Software OBS aufgezeichnet, um | E3: Speaker 2
A4: 1 | B4: 16450 | C4: 22550 | D4: das dann später zu transkribieren und die Audio wird dann nach der Transkription gelöfft | E4: Speaker 2
A5: 1 | B5: 22550 | C5: 28670 | D5: und du kannst auch während des Interviews immer stoppen und deine Einwilligungen zurückziehen | E5: Speaker 2
A6: 1 | B6: 28670 | C6: 35210 | D6: ohne irgendwelche Gründe zu benennen oder negative Folgen davon zu bekommen und deswegen | E6: Speaker 2
A7: 1 | B7: 35210 | C7: 38090 | D7: einmal die Frage, ob du damit einverstanden bist, dass ich das aufzeichne? | E7: Speaker 2
A8: 1 | B8: 39390 | C8: 39550 | D8: Ja. | E8: Speaker 2
A9: 1 | B9: 40250 | C9: 41070 | D9: Okay, perfekt. | E9: Speaker 2
A10: 1 | B10: 42690 | C10: 50650 | D10: Und genau, dann einmal zur Struktur, also du hast ja schon den Link bekommen zu der App | E10: Speaker 2
A11: 1 | B11: 51530 | C11: 57910 | D11: und das sieht wie folgendermaßen aus, die Nutzerstudie, zuerst musst du ein kleines Onboarding | E11: Speaker 2
A12: 1 | B12: 57910 | C12: 65030 | D12: machen, um ein paar Fragen zu beantworten, dann hast du eine Konversation als Warm-up | E12: Speaker 2
A13: 1 | B13: 65030 | C13: 70770 | D13: und dann zwei weitere Konversationen und nach jeder Konversation hast du nochmal so eine | E13: Speaker 2
A14: 1 | B14: 70770 | C14: 77710 | D14: kurze Übersicht, so eine Art Summary, die du dann auf deinem Bildschirm siehst, die | E14: Speaker 2
... A28: 1 | B28: 244530 | C28: 244870 | D28: Okay. | E28: Speaker 1
A29: 1 | B29: 247190 | C29: 252470 | D29: Ja, ich glaube, die Language-Level hier sind relativ übersichtlich, da bin ich auf jeden Fall hier. | E29: Speaker 1 | I29: GEN_UI_UX
A30: 1 | B30: 255730 | C30: 258329 | D30: Ich schreibe so ein bisschen mit, wenn nicht, dass du dich wunderst. | E30: Speaker 2
A31: 1 | B31: 259630 | C31: 263250 | D31: Ja, meine Muttersprache ist Deutsch. | E31: Speaker 1
A32: 1 | B32: 263250 | C32: 266610 | D32: Ah, ich kann nur eine auswählen, okay. | E32: Speaker 1
A33: 1 | B33: 268730 | C33: 271330 | D33: Aber ist bei mir auch richtig mit einer Muttersprache? | E33: Speaker 1
A34: 1 | B34: 279480 | C34: 286180 | D34: Do you struggle with up to five? | E34: Speaker 1
A35: 1 | B35: 286360 | C35: 286560 | D35: Okay. | E35: Speaker 1
A36: 1 | B36: 289830 | C36: 295250 | D36: Boah, ja, die Gendern im Spanischen kann ich mir nicht so merken. | E36: Speaker 1
A37: 1 | B37: 296710 | C37: 298050 | D37: Mathikregeln auch noch schwierig. | E37: Speaker 1
A38: 1 | B38: 300770 | C38: 314520 | D38: Die Frage ist, gehe ich jetzt eher auf die Sachen, die halt so ganz schwer sind, oder so Sachen, mit denen ich auch noch struggle. | E38: Speaker 1
A39: 1 | B39: 315240 | C39: 317980 | D39: Eigentlich bin ich gerade eher, glaube ich, mir am vieren abwählen. | E39: Speaker 1
A40: 1 | B40: 321980 | C40: 324620 | D40: Ja, four-leaf-speaking ist reine Kopfsache. | E40: Speaker 1
A41: 1 | B41: 325660 | C41: 327440 | D41: Ja, konjugieren ist immer ein bisschen schwierig. | E41: Speaker 1
... A66: 1 | B66: 531250 | C66: 533550 | D66: Das sollte vielleicht nicht mal beim selben rauskommen. | E66: Speaker 1
A67: 1 | B67: 539500 | C67: 541360 | D67: Sieht lustig aus. | E67: Speaker 2 | I67: CUST_Partner
A68: 1 | B68: 542060 | C68: 544460 | D68: Du musst nach oben den Namen eingeben. | E68: Speaker 2
A69: 1 | B69: 545200 | C69: 546640 | D69: Oh, ich muss den Namen eingeben, ja. | E69: Speaker 2
A70: 1 | B70: 548860 | C70: 551640 | D70: Stimmt, wer nicht blind ist. | E70: Speaker 1
A71: 1 | B71: 556650 | C71: 561750 | D71: Wenn ich mich jetzt schon einmal Frucht benannt habe, dann kriegt ihr jetzt auch einen Fruchtnamen. | E71: Speaker 1
A72: 1 | B72: 564330 | C72: 567390 | D72: Okay, also ich vermute, das ist jetzt das erste Szenario. | E72: Speaker 1
A73: 1 | B73: 572250 | C73: 574250 | D73: Okay, dann Generate Task. | E73: Speaker 1
A74: 1 | B74: 574490 | C74: 576250 | D74: Klingt so, als müsste ich jetzt ein paar Aufgaben. | E74: Speaker 2
A75: 1 | B75: 576250 | C75: 578530 | D75: Genau, bevor du weitergehst. | E75: Speaker 2
A76: 1 | B76: 579030 | C76: 584190 | D76: Auch wichtig, jedes Szenario oder jeder Chat hat ein Limit. | E76: Speaker 2
A77: 1 | B77: 584450 | C77: 587210 | D77: Also man kann maximal 15 Nachrichten schreiben. | E77: Speaker 2
...

Sheet Code List
A1: RQs | B1: Category | C1: Code | D1: Description
A2: RQ1 - UX | B2: UX (User Experience) | C2: UX_Emotion | D2: Statements regarding the emotional state, enjoyment, and hedonic quality of the interaction.
C3: UX_Efficiency | D3: Perceived efficiency, smoothness, and goal-attainment speed during the conversation.
C4: UX_Frustration | D4: Mentions of confusion, cognitive overload, or moments where the system blocked the user's progress.
C5: UX_UsageIntention | D5: Explicit statements about the intention to use the system for future language practice outside the study.
A6: RQ1 - Personalization | B6: PER (Personalization) | C6: PER_Adaption | D6: The user's general awareness or failure to notice the customized elements within the prompt.
C7: PER_Level | D7: Perception of how well the system's vocabulary and complexity matched the user's A1-A2 proficiency.
C8: PER_TaskAdaption | D8: How dynamically the partner reacted to the user's specific conversational inputs and roleplay attempts.
C9: PER_MistakeHandling | D9: Feedback on how the system addressed, corrected, or ignored language mistakes and struggles.
A10: RQ2 - Learning Outcomes | B10: LEARN (Perceived Learning) | C10: LEARN_Productivity | D10: The perceived impact of the conversation on the user's specific language learning goals.
C11: LEARN_Confidence | D11: The effect of the interaction on the user's confidence and willingness to speak freely.
A12: RQ3 - Customization | B12: CUST (Customization) | C12: CUST_Partner | D12: Statements regarding the customized partner.
C13: CUST_Motivation | D13: Reasons and motivations behind the specific choices made during the avatar and profile setup.
C14: CUST_Rating | D14: Evaluation and feedback regarding the available onboarding options (e.g., hobbies, interests).
C15: CUST_Missing | D15: Explicit requests for additional customization features that were not present in the current system.
B16: COMP / GEN (Comparisons) | C16: COMP_Preference | D16: The overarching preference for either Chat 1 or Chat 2 and the main rationale behind it.
C17: COMP_Variant | D17: The user's guess regarding which conversation utilized the personalized LLM prompt.
C18: GEN_Improvement | D18: General ideas, feature requests, and suggestions to improve the application.
C19: GEN_UI_UX | D19: Researcher notes on general interface issues, bugs, or UI/UX problems not related to the LLM prompt.
B20: OBS (Observations) | C20: OBS_UserBehavior | D20: Researcher notes on actual system usage, task performance, and hint reliance during the session.
B21: CONF (Confounders) | C21: CONF_Scenario | D21: Bias introduced by the user's personal preference for the conversational setting (e.g., Cafe vs. Market).
C22: CONF_TaskPerformance | D22: Methodological artifacts where a lack of user errors prevented the system from delivering personalized feedback.
C23: CONF_Timeframe | D23: Limitations arising from the short study duration preventing the establishment of a deeper user-AI relationship.
C24: CONF_Others | D24: Confounding variables different to the three above.

Sheet Phases
A1: Onboarding
A2: Warmup
A3: Chat 1
A4: Chat 2
A5: Summary
A6: Evaluation
A7: General

Sheet comparative_sys_preference
A1: pid | B1: group | C1: overall_preference | D1: ref | E1: more_efficient | F1: ref | G1: less_frustrating | H1: ref | I1: more_productive | J1: ref | K1: more_confident | L1: ref | M1: more_level_adapted | N1: ref | O1: more_task_adapted | P1: ref | Q1: better_mistake_handling | R1: ref | S1: experiment_guess | T1: ref
A2: 1 | B2: =_xlfn.XLOOKUP(A2,participants!A:A,participants!C:C) -> control_first | C2: experiment | D2: =ROW(Cleaned_Transcripts!E585) -> 585 | E2: control | F2: =ROW(Cleaned_Transcripts!E631) -> 631 | G2: experiment | H2: =ROW(Cleaned_Transcripts!E651) -> 651 | I2: experiment | J2: =ROW(Cleaned_Transcripts!E656) -> 656 | K2: experiment | L2: =ROW(Cleaned_Transcripts!E659) -> 659 | M2: experiment | N2: =ROW(Cleaned_Transcripts!E664) -> 664 | O2: neutral | P2: =ROW(Cleaned_Transcripts!E672) -> 672 | Q2: experiment | R2: =ROW(Cleaned_Transcripts!E681) -> 681 | S2: experiment | T2: =ROW(Cleaned_Transcripts!E735) -> 735
A3: 2 | B3: =_xlfn.XLOOKUP(A3,participants!A:A,participants!C:C) -> experiment_first | C3: experiment | D3: =ROW(Cleaned_Transcripts!E1326) -> 1326 | E3: experiment | F3: =ROW(Cleaned_Transcripts!E1380) -> 1380 | G3: experiment | H3: =ROW(Cleaned_Transcripts!E1340) -> 1340 | I3: control | J3: =ROW(Cleaned_Transcripts!E1400) -> 1400 | K3: control | L3: =ROW(Cleaned_Transcripts!E1406) -> 1406 | M3: neutral | N3: =ROW(Cleaned_Transcripts!E1429) -> 1429 | O3: control | P3: =ROW(Cleaned_Transcripts!E1448) -> 1448 | Q3: control | R3: =ROW(Cleaned_Transcripts!E1343) -> 1343 | S3: control | T3: =ROW(Cleaned_Transcripts!E1517) -> 1517
A4: 3 | B4: =_xlfn.XLOOKUP(A4,participants!A:A,participants!C:C) -> experiment_first | C4: experiment | D4: =ROW(Cleaned_Transcripts!E1804) -> 1804 | E4: experiment | F4: =ROW(Cleaned_Transcripts!E1853) -> 1853 | G4: neutral | H4: =ROW(Cleaned_Transcripts!E1859) -> 1859 | I4: neutral | J4: =ROW(Cleaned_Transcripts!E1878) -> 1878 | K4: neutral | L4: -1 | M4: neutral | N4: -1 | O4: experiment | P4: =ROW(Cleaned_Transcripts!E1891) -> 1891 | Q4: control | R4: =ROW(Cleaned_Transcripts!E1929) -> 1929 | S4: experiment | T4: =ROW(Cleaned_Transcripts!E1968) -> 1968
A5: 4 | B5: =_xlfn.XLOOKUP(A5,participants!A:A,participants!C:C) -> control_first | C5: experiment | D5: =ROW(Cleaned_Transcripts!E2222) -> 2222 | E5: neutral | F5: =ROW(Cleaned_Transcripts!E2256) -> 2256 | G5: experiment | H5: =ROW(Cleaned_Transcripts!E2266) -> 2266 | I5: control | J5: =ROW(Cleaned_Transcripts!E2269) -> 2269 | K5: experiment | L5: =ROW(Cleaned_Transcripts!E2275) -> 2275 | M5: neutral | N5: =ROW(Cleaned_Transcripts!E2278) -> 2278 | O5: neutral | P5: -1 | Q5: experiment | R5: =ROW(Cleaned_Transcripts!E2306) -> 2306 | S5: neutral | T5: =ROW(Cleaned_Transcripts!E2347) -> 2347
A6: 5 | B6: =_xlfn.XLOOKUP(A6,participants!A:A,participants!C:C) -> experiment_first | C6: experiment | D6: =ROW(Cleaned_Transcripts!E2651) -> 2651 | E6: experiment | F6: =ROW(Cleaned_Transcripts!E2676) -> 2676 | G6: experiment | H6: =ROW(Cleaned_Transcripts!E2692) -> 2692 | I6: control | J6: =ROW(Cleaned_Transcripts!E2694) -> 2694 | K6: experiment | L6: =ROW(Cleaned_Transcripts!E2697) -> 2697 | M6: neutral | N6: =ROW(Cleaned_Transcripts!E2706) -> 2706 | O6: control | P6: =ROW(Cleaned_Transcripts!E2713) -> 2713 | Q6: experiment | R6: =ROW(Cleaned_Transcripts!E2719) -> 2719 | S6: experiment | T6: =ROW(Cleaned_Transcripts!E2760) -> 2760
A7: 6 | B7: =_xlfn.XLOOKUP(A7,participants!A:A,participants!C:C) -> control_first | C7: control | D7: =ROW(Cleaned_Transcripts!E3158) -> 3158 | E7: neutral | F7: =ROW(Cleaned_Transcripts!E3221) -> 3221 | G7: control | H7: =ROW(Cleaned_Transcripts!E3258) -> 3258 | I7: control | J7: =ROW(Cleaned_Transcripts!E3265) -> 3265 | K7: control | L7: =ROW(Cleaned_Transcripts!E3360) -> 3360 | M7: neutral | N7: -1 | O7: neutral | P7: =ROW(Cleaned_Transcripts!E3395) -> 3395 | Q7: neutral | R7: =ROW(Cleaned_Transcripts!E3398) -> 3398 | S7: control | T7: =ROW(Cleaned_Transcripts!E3507) -> 3507
A8: 7 | B8: =_xlfn.XLOOKUP(A8,participants!A:A,participants!C:C) -> experiment_first | C8: experiment | D8: =ROW(Cleaned_Transcripts!E4018) -> 4018 | E8: experiment | F8: =ROW(Cleaned_Transcripts!E4041) -> 4041 | G8: experiment | H8: =ROW(Cleaned_Transcripts!E4023) -> 4023 | I8: control | J8: =ROW(Cleaned_Transcripts!E4060) -> 4060 | K8: experiment | L8: =ROW(Cleaned_Transcripts!E4062) -> 4062 | M8: neutral | N8: =ROW(Cleaned_Transcripts!E4064) -> 4064 | O8: neutral | P8: =ROW(Cleaned_Transcripts!E4103) -> 4103 | Q8: control | R8: =ROW(Cleaned_Transcripts!E4117) -> 4117 | S8: control | T8: =ROW(Cleaned_Transcripts!E4183) -> 4183
A9: 8 | B9: =_xlfn.XLOOKUP(A9,participants!A:A,participants!C:C) -> experiment_first | C9: control | D9: =ROW(Cleaned_Transcripts!E4665) -> 4665 | E9: control | F9: =ROW(Cleaned_Transcripts!E4719) -> 4719 | G9: control | H9: =ROW(Cleaned_Transcripts!E4724) -> 4724 | I9: experiment | J9: =ROW(Cleaned_Transcripts!E4726) -> 4726 | K9: control | L9: =ROW(Cleaned_Transcripts!E4729) -> 4729 | M9: control | N9: =ROW(Cleaned_Transcripts!E4733) -> 4733 | O9: control | P9: =ROW(Cleaned_Transcripts!E4746) -> 4746 | Q9: control | R9: =ROW(Cleaned_Transcripts!E4749) -> 4749 | S9: control | T9: =ROW(Cleaned_Transcripts!E4789) -> 4789
A10: 9 | B10: =_xlfn.XLOOKUP(A10,participants!A:A,participants!C:C) -> control_first | C10: control | D10: =ROW(Cleaned_Transcripts!E5562) -> 5562 | E10: control | F10: =ROW(Cleaned_Transcripts!E5602) -> 5602 | G10: control | H10: =ROW(Cleaned_Transcripts!E5613) -> 5613 | I10: experiment | J10: =ROW(Cleaned_Transcripts!E5624) -> 5624 | K10: neutral | L10: =ROW(Cleaned_Transcripts!E5636) -> 5636 | M10: neutral | N10: =ROW(Cleaned_Transcripts!E5644) -> 5644 | O10: control | P10: =ROW(Cleaned_Transcripts!E5667) -> 5667 | Q10: control | R10: =ROW(Cleaned_Transcripts!E5677) -> 5677 | S10: experiment | T10: =ROW(Cleaned_Transcripts!E5709) -> 5709
A11: 10 | B11: =_xlfn.XLOOKUP(A11,participants!A:A,participants!C:C) -> control_first | C11: control | D11: =ROW(Cleaned_Transcripts!E5879) -> 5879 | E11: neutral | F11: =ROW(Cleaned_Transcripts!E5893) -> 5893 | G11: experiment | H11: =ROW(Cleaned_Transcripts!E5897) -> 5897 | I11: control | J11: =ROW(Cleaned_Transcripts!E5899) -> 5899 | K11: control | L11: =ROW(Cleaned_Transcripts!E5901) -> 5901 | M11: control | N11: =ROW(Cleaned_Transcripts!E5906) -> 5906 | O11: experiment | P11: =ROW(Cleaned_Transcripts!E5912) -> 5912 | Q11: neutral | R11: =ROW(Cleaned_Transcripts!E5917) -> 5917 | S11: experiment | T11: =ROW(Cleaned_Transcripts!E5940) -> 5940
A12: 11 | B12: =_xlfn.XLOOKUP(A12,participants!A:A,participants!C:C) -> experiment_first | C12: control | D12: =ROW(Cleaned_Transcripts!E6597) -> 6597 | E12: experiment | F12: =ROW(Cleaned_Transcripts!E6634) -> 6634 | G12: neutral | H12: =ROW(Cleaned_Transcripts!E6642) -> 6642 | I12: control | J12: =ROW(Cleaned_Transcripts!E6644) -> 6644 | K12: control | L12: =ROW(Cleaned_Transcripts!E6647) -> 6647 | M12: neutral | N12: =ROW(Cleaned_Transcripts!E6653) -> 6653 | O12: neutral | P12: =ROW(Cleaned_Transcripts!E6662) -> 6662 | Q12: experiment | R12: =ROW(Cleaned_Transcripts!E6605) -> 6605 | S12: control | T12: =ROW(Cleaned_Transcripts!E6690) -> 6690
A13: 12 | B13: =_xlfn.XLOOKUP(A13,participants!A:A,participants!C:C) -> control_first | C13: control | D13: =ROW(Cleaned_Transcripts!E7035) -> 7035 | E13: control | F13: =ROW(Cleaned_Transcripts!E7065) -> 7065 | G13: control | H13: =ROW(Cleaned_Transcripts!E7072) -> 7072 | I13: neutral | J13: -1 | K13: neutral | L13: -1 | M13: neutral | N13: =ROW(Cleaned_Transcripts!E7079) -> 7079 | O13: control | P13: =ROW(Cleaned_Transcripts!E7083) -> 7083 | Q13: experiment | R13: =ROW(Cleaned_Transcripts!E7091) -> 7091 | S13: control | T13: =ROW(Cleaned_Transcripts!E7117) -> 7117
A14: 13 | B14: =_xlfn.XLOOKUP(A14,participants!A:A,participants!C:C) -> control_first | C14: control | D14: =ROW(Cleaned_Transcripts!E7801) -> 7801 | E14: neutral | F14: =ROW(Cleaned_Transcripts!E7846) -> 7846 | G14: neutral | H14: =ROW(Cleaned_Transcripts!E7856) -> 7856 | I14: neutral | J14: =ROW(Cleaned_Transcripts!E7859) -> 7859 | K14: neutral | L14: =ROW(Cleaned_Transcripts!E7860) -> 7860 | M14: neutral | N14: =ROW(Cleaned_Transcripts!E7866) -> 7866 | O14: neutral | P14: =ROW(Cleaned_Transcripts!E7885) -> 7885 | Q14: neutral | R14: =ROW(Cleaned_Transcripts!E7894) -> 7894 | S14: neutral | T14: =ROW(Cleaned_Transcripts!E7951) -> 7951
A15: 14 | B15: =_xlfn.XLOOKUP(A15,participants!A:A,participants!C:C) -> experiment_first | C15: control | D15: =ROW(Cleaned_Transcripts!E8215) -> 8215 | E15: neutral | F15: =ROW(Cleaned_Transcripts!E8240) -> 8240 | G15: control | H15: =ROW(Cleaned_Transcripts!E8252) -> 8252 | I15: experiment | J15: =ROW(Cleaned_Transcripts!E8253) -> 8253 | K15: control | L15: =ROW(Cleaned_Transcripts!E8254) -> 8254 | M15: neutral | N15: =ROW(Cleaned_Transcripts!E8255) -> 8255 | O15: neutral | P15: =ROW(Cleaned_Transcripts!E8261) -> 8261 | Q15: neutral | R15: =ROW(Cleaned_Transcripts!E8265) -> 8265 | S15: experiment | T15: =ROW(Cleaned_Transcripts!E8302) -> 8302
A16: 15 | B16: =_xlfn.XLOOKUP(A16,participants!A:A,participants!C:C) -> experiment_first | C16: experiment | D16: =ROW(Cleaned_Transcripts!E8605) -> 8605 | E16: experiment | F16: =ROW(Cleaned_Transcripts!E8618) -> 8618 | G16: experiment | H16: =ROW(Cleaned_Transcripts!E8627) -> 8627 | I16: experiment | J16: =ROW(Cleaned_Transcripts!E8630) -> 8630 | K16: neutral | L16: =ROW(Cleaned_Transcripts!E8634) -> 8634 | M16: experiment | N16: =ROW(Cleaned_Transcripts!E8635) -> 8635 | O16: experiment | P16: =ROW(Cleaned_Transcripts!E8647) -> 8647 | Q16: neutral | R16: =ROW(Cleaned_Transcripts!E8651) -> 8651 | S16: experiment | T16: =ROW(Cleaned_Transcripts!E8693) -> 8693
A17: 16 | B17: =_xlfn.XLOOKUP(A17,participants!A:A,participants!C:C) -> experiment_first | C17: control | D17: =ROW(Cleaned_Transcripts!E9186) -> 9186 | E17: neutral | F17: =ROW(Cleaned_Transcripts!E9221) -> 9221 | G17: control | H17: =ROW(Cleaned_Transcripts!E9236) -> 9236 | I17: neutral | J17: =ROW(Cleaned_Transcripts!E9237) -> 9237 | K17: control | L17: =ROW(Cleaned_Transcripts!E9239) -> 9239 | M17: control | N17: =ROW(Cleaned_Transcripts!E9248) -> 9248 | O17: control | P17: =ROW(Cleaned_Transcripts!E9258) -> 9258 | Q17: neutral | R17: -1 | S17: control | T17: =ROW(Cleaned_Transcripts!E9323) -> 9323
A18: 17 | B18: =_xlfn.XLOOKUP(A18,participants!A:A,participants!C:C) -> control_first | C18: neutral | D18: =ROW(Cleaned_Transcripts!E9621) -> 9621 | E18: neutral | F18: =ROW(Cleaned_Transcripts!E9636) -> 9636 | G18: neutral | H18: -1 | I18: neutral | J18: =ROW(Cleaned_Transcripts!E9640) -> 9640 | K18: neutral | L18: =ROW(Cleaned_Transcripts!E9642) -> 9642 | M18: neutral | N18: =ROW(Cleaned_Transcripts!E9646) -> 9646 | O18: neutral | P18: =ROW(Cleaned_Transcripts!E9654) -> 9654 | Q18: neutral | R18: =ROW(Cleaned_Transcripts!E9656) -> 9656 | S18: neutral | T18: =ROW(Cleaned_Transcripts!E9694) -> 9694
A19: 18 | B19: =_xlfn.XLOOKUP(A19,participants!A:A,participants!C:C) -> control_first | C19: experiment | D19: =ROW(Cleaned_Transcripts!E10220) -> 10220 | E19: experiment | F19: =ROW(Cleaned_Transcripts!E10291) -> 10291 | G19: neutral | H19: -1 | I19: control | J19: =ROW(Cleaned_Transcripts!E10299) -> 10299 | K19: control | L19: =ROW(Cleaned_Transcripts!E10302) -> 10302 | M19: experiment | N19: =ROW(Cleaned_Transcripts!E10304) -> 10304 | O19: experiment | P19: =ROW(Cleaned_Transcripts!E10311) -> 10311 | Q19: experiment | R19: =ROW(Cleaned_Transcripts!E10313) -> 10313 | S19: experiment | T19: =ROW(Cleaned_Transcripts!E10348) -> 10348
A20: 19 | B20: =_xlfn.XLOOKUP(A20,participants!A:A,participants!C:C) -> experiment_first | C20: experiment | D20: =ROW(Cleaned_Transcripts!E11275) -> 11275 | E20: control | F20: =ROW(Cleaned_Transcripts!E11280) -> 11280 | G20: control | H20: =ROW(Cleaned_Transcripts!E11282) -> 11282 | I20: experiment | J20: =ROW(Cleaned_Transcripts!E11298) -> 11298 | K20: control | L20: =ROW(Cleaned_Transcripts!E11299) -> 11299 | M20: control | N20: =ROW(Cleaned_Transcripts!E11302) -> 11302 | O20: experiment | P20: =ROW(Cleaned_Transcripts!E11314) -> 11314 | Q20: neutral | R20: =ROW(Cleaned_Transcripts!E11318) -> 11318 | S20: experiment | T20: =ROW(Cleaned_Transcripts!E11348) -> 11348
A21: 20 | B21: =_xlfn.XLOOKUP(A21,participants!A:A,participants!C:C) -> control_first | C21: experiment | D21: =ROW(Cleaned_Transcripts!E11747) -> 11747 | E21: experiment | F21: =ROW(Cleaned_Transcripts!E11774) -> 11774 | G21: experiment | H21: =ROW(Cleaned_Transcripts!E11778) -> 11778 | I21: experiment | J21: =ROW(Cleaned_Transcripts!E11782) -> 11782 | K21: experiment | L21: =ROW(Cleaned_Transcripts!E11783) -> 11783 | M21: experiment | N21: =ROW(Cleaned_Transcripts!E11797) -> 11797 | O21: experiment | P21: =ROW(Cleaned_Transcripts!E11802) -> 11802 | Q21: experiment | R21: =ROW(Cleaned_Transcripts!E11804) -> 11804 | S21: experiment | T21: =ROW(Cleaned_Transcripts!E11856) -> 11856

Sheet Cleaned_Transcripts
A1: participant_id | B1: start | C1: end | D1: guess | E1: text | F1: speaker | G1: group | H1: variant | I1: source_type | J1: main_phase | K1: sub_phase | L1: deductive_code | M1: quotes | N1: inductive_codes
A2: 1 | B2: 1029 | C2: 9370 | E2: Ja, dann nochmal danke dir, dass du dir die Zeit genommen hast und die Nutzerstudie dauert | F2: Speaker 2 | G2: =_xlfn.XLOOKUP(A2,participants!A:A,participants!C:C) -> control_first | H2: =IF(J2 = "Chat 1", IF(P01__1[[#This Row],[group]] = "control_first", "control", "experiment"), IF(J2 = "Chat 2", IF(P01__1[[#This Row],[group]] = "control_first", "experiment", "control"), "")) | J2: General
A3: 1 | B3: 9370 | C3: 16450 | E3: so ungefähr 45 bis 60 Minuten, das Interview wird mit der Software OBS aufgezeichnet, um | F3: Speaker 2 | G3: =_xlfn.XLOOKUP(A3,participants!A:A,participants!C:C) -> control_first | H3: =IF(J3 = "Chat 1", IF(P01__1[[#This Row],[group]] = "control_first", "control", "experiment"), IF(J3 = "Chat 2", IF(P01__1[[#This Row],[group]] = "control_first", "experiment", "control"), "")) | J3: General
A4: 1 | B4: 16450 | C4: 22550 | E4: das dann später zu transkribieren und die Audio wird dann nach der Transkription gelöfft | F4: Speaker 2 | G4: =_xlfn.XLOOKUP(A4,participants!A:A,participants!C:C) -> control_first | H4: =IF(J4 = "Chat 1", IF(P01__1[[#This Row],[group]] = "control_first", "control", "experiment"), IF(J4 = "Chat 2", IF(P01__1[[#This Row],[group]] = "control_first", "experiment", "control"), "")) | J4: General
A5: 1 | B5: 22550 | C5: 28670 | E5: und du kannst auch während des Interviews immer stoppen und deine Einwilligungen zurückziehen | F5: Speaker 2 | G5: =_xlfn.XLOOKUP(A5,participants!A:A,participants!C:C) -> control_first | H5: =IF(J5 = "Chat 1", IF(P01__1[[#This Row],[group]] = "control_first", "control", "experiment"), IF(J5 = "Chat 2", IF(P01__1[[#This Row],[group]] = "control_first", "experiment", "control"), "")) | J5: General
A6: 1 | B6: 28670 | C6: 35210 | E6: ohne irgendwelche Gründe zu benennen oder negative Folgen davon zu bekommen und deswegen | F6: Speaker 2 | G6: =_xlfn.XLOOKUP(A6,participants!A:A,participants!C:C) -> control_first | H6: =IF(J6 = "Chat 1", IF(P01__1[[#This Row],[group]] = "control_first", "control", "experiment"), IF(J6 = "Chat 2", IF(P01__1[[#This Row],[group]] = "control_first", "experiment", "control"), "")) | J6: General
A7: 1 | B7: 35210 | C7: 38090 | E7: einmal die Frage, ob du damit einverstanden bist, dass ich das aufzeichne? | F7: Speaker 2 | G7: =_xlfn.XLOOKUP(A7,participants!A:A,participants!C:C) -> control_first | H7: =IF(J7 = "Chat 1", IF(P01__1[[#This Row],[group]] = "control_first", "control", "experiment"), IF(J7 = "Chat 2", IF(P01__1[[#This Row],[group]] = "control_first", "experiment", "control"), "")) | J7: General
A8: 1 | B8: 39390 | C8: 39550 | E8: Ja. | F8: Speaker 2 | G8: =_xlfn.XLOOKUP(A8,participants!A:A,participants!C:C) -> control_first | H8: =IF(J8 = "Chat 1", IF(P01__1[[#This Row],[group]] = "control_first", "control", "experiment"), IF(J8 = "Chat 2", IF(P01__1[[#This Row],[group]] = "control_first", "experiment", "control"), "")) | J8: General
A9: 1 | B9: 40250 | C9: 41070 | E9: Okay, perfekt. | F9: Speaker 2 | G9: =_xlfn.XLOOKUP(A9,participants!A:A,participants!C:C) -> control_first | H9: =IF(J9 = "Chat 1", IF(P01__1[[#This Row],[group]] = "control_first", "control", "experiment"), IF(J9 = "Chat 2", IF(P01__1[[#This Row],[group]] = "control_first", "experiment", "control"), "")) | J9: General
A10: 1 | B10: 42690 | C10: 50650 | E10: Und genau, dann einmal zur Struktur, also du hast ja schon den Link bekommen zu der App | F10: Speaker 2 | G10: =_xlfn.XLOOKUP(A10,participants!A:A,participants!C:C) -> control_first | H10: =IF(J10 = "Chat 1", IF(P01__1[[#This Row],[group]] = "control_first", "control", "experiment"), IF(J10 = "Chat 2", IF(P01__1[[#This Row],[group]] = "control_first", "experiment", "control"), "")) | J10: General
A11: 1 | B11: 51530 | C11: 57910 | E11: und das sieht wie folgendermaßen aus, die Nutzerstudie, zuerst musst du ein kleines Onboarding | F11: Speaker 2 | G11: =_xlfn.XLOOKUP(A11,participants!A:A,participants!C:C) -> control_first | H11: =IF(J11 = "Chat 1", IF(P01__1[[#This Row],[group]] = "control_first", "control", "experiment"), IF(J11 = "Chat 2", IF(P01__1[[#This Row],[group]] = "control_first", "experiment", "control"), "")) | J11: General
A12: 1 | B12: 57910 | C12: 65030 | E12: machen, um ein paar Fragen zu beantworten, dann hast du eine Konversation als Warm-up | F12: Speaker 2 | G12: =_xlfn.XLOOKUP(A12,participants!A:A,participants!C:C) -> control_first | H12: =IF(J12 = "Chat 1", IF(P01__1[[#This Row],[group]] = "control_first", "control", "experiment"), IF(J12 = "Chat 2", IF(P01__1[[#This Row],[group]] = "control_first", "experiment", "control"), "")) | J12: General
A13: 1 | B13: 65030 | C13: 70770 | E13: und dann zwei weitere Konversationen und nach jeder Konversation hast du nochmal so eine | F13: Speaker 2 | G13: =_xlfn.XLOOKUP(A13,participants!A:A,participants!C:C) -> control_first | H13: =IF(J13 = "Chat 1", IF(P01__1[[#This Row],[group]] = "control_first", "control", "experiment"), IF(J13 = "Chat 2", IF(P01__1[[#This Row],[group]] = "control_first", "experiment", "control"), "")) | J13: General
... A28: 1 | B28: 244530 | C28: 244870 | E28: Okay. | F28: Speaker 1 | G28: =_xlfn.XLOOKUP(A28,participants!A:A,participants!C:C) -> control_first | H28: =IF(J28 = "Chat 1", IF(P01__1[[#This Row],[group]] = "control_first", "control", "experiment"), IF(J28 = "Chat 2", IF(P01__1[[#This Row],[group]] = "control_first", "experiment", "control"), "")) | J28: General
A29: 1 | B29: 247190 | C29: 252470 | E29: Ja, ich glaube, die Language-Level hier sind relativ übersichtlich, da bin ich auf jeden Fall hier. | F29: Speaker 1 | G29: =_xlfn.XLOOKUP(A29,participants!A:A,participants!C:C) -> control_first | H29: =IF(J29 = "Chat 1", IF(P01__1[[#This Row],[group]] = "control_first", "control", "experiment"), IF(J29 = "Chat 2", IF(P01__1[[#This Row],[group]] = "control_first", "experiment", "control"), "")) | J29: Onboarding | L29: GEN_UI_UX
A30: 1 | B30: 255730 | C30: 258329 | E30: Ich schreibe so ein bisschen mit, wenn nicht, dass du dich wunderst. | F30: Speaker 2 | G30: =_xlfn.XLOOKUP(A30,participants!A:A,participants!C:C) -> control_first | H30: =IF(J30 = "Chat 1", IF(P01__1[[#This Row],[group]] = "control_first", "control", "experiment"), IF(J30 = "Chat 2", IF(P01__1[[#This Row],[group]] = "control_first", "experiment", "control"), "")) | J30: Onboarding
A31: 1 | B31: 259630 | C31: 263250 | E31: Ja, meine Muttersprache ist Deutsch. | F31: Speaker 1 | G31: =_xlfn.XLOOKUP(A31,participants!A:A,participants!C:C) -> control_first | H31: =IF(J31 = "Chat 1", IF(P01__1[[#This Row],[group]] = "control_first", "control", "experiment"), IF(J31 = "Chat 2", IF(P01__1[[#This Row],[group]] = "control_first", "experiment", "control"), "")) | J31: Onboarding
A32: 1 | B32: 263250 | C32: 266610 | E32: Ah, ich kann nur eine auswählen, okay. | F32: Speaker 1 | G32: =_xlfn.XLOOKUP(A32,participants!A:A,participants!C:C) -> control_first | H32: =IF(J32 = "Chat 1", IF(P01__1[[#This Row],[group]] = "control_first", "control", "experiment"), IF(J32 = "Chat 2", IF(P01__1[[#This Row],[group]] = "control_first", "experiment", "control"), "")) | J32: Onboarding
A33: 1 | B33: 268730 | C33: 271330 | E33: Aber ist bei mir auch richtig mit einer Muttersprache? | F33: Speaker 1 | G33: =_xlfn.XLOOKUP(A33,participants!A:A,participants!C:C) -> control_first | H33: =IF(J33 = "Chat 1", IF(P01__1[[#This Row],[group]] = "control_first", "control", "experiment"), IF(J33 = "Chat 2", IF(P01__1[[#This Row],[group]] = "control_first", "experiment", "control"), "")) | J33: Onboarding
A34: 1 | B34: 279480 | C34: 286180 | E34: Do you struggle with up to five? | F34: Speaker 1 | G34: =_xlfn.XLOOKUP(A34,participants!A:A,participants!C:C) -> control_first | H34: =IF(J34 = "Chat 1", IF(P01__1[[#This Row],[group]] = "control_first", "control", "experiment"), IF(J34 = "Chat 2", IF(P01__1[[#This Row],[group]] = "control_first", "experiment", "control"), "")) | J34: Onboarding
A35: 1 | B35: 286360 | C35: 286560 | E35: Okay. | F35: Speaker 1 | G35: =_xlfn.XLOOKUP(A35,participants!A:A,participants!C:C) -> control_first | H35: =IF(J35 = "Chat 1", IF(P01__1[[#This Row],[group]] = "control_first", "control", "experiment"), IF(J35 = "Chat 2", IF(P01__1[[#This Row],[group]] = "control_first", "experiment", "control"), "")) | J35: Onboarding
A36: 1 | B36: 289830 | C36: 295250 | E36: Boah, ja, die Gendern im Spanischen kann ich mir nicht so merken. | F36: Speaker 1 | G36: =_xlfn.XLOOKUP(A36,participants!A:A,participants!C:C) -> control_first | H36: =IF(J36 = "Chat 1", IF(P01__1[[#This Row],[group]] = "control_first", "control", "experiment"), IF(J36 = "Chat 2", IF(P01__1[[#This Row],[group]] = "control_first", "experiment", "control"), "")) | J36: Onboarding
A37: 1 | B37: 296710 | C37: 298050 | E37: Mathikregeln auch noch schwierig. | F37: Speaker 1 | G37: =_xlfn.XLOOKUP(A37,participants!A:A,participants!C:C) -> control_first | H37: =IF(J37 = "Chat 1", IF(P01__1[[#This Row],[group]] = "control_first", "control", "experiment"), IF(J37 = "Chat 2", IF(P01__1[[#This Row],[group]] = "control_first", "experiment", "control"), "")) | J37: Onboarding
A38: 1 | B38: 300770 | C38: 314520 | E38: Die Frage ist, gehe ich jetzt eher auf die Sachen, die halt so ganz schwer sind, oder so Sachen, mit denen ich auch noch struggle. | F38: Speaker 1 | G38: =_xlfn.XLOOKUP(A38,participants!A:A,participants!C:C) -> control_first | H38: =IF(J38 = "Chat 1", IF(P01__1[[#This Row],[group]] = "control_first", "control", "experiment"), IF(J38 = "Chat 2", IF(P01__1[[#This Row],[group]] = "control_first", "experiment", "control"), "")) | J38: Onboarding
A39: 1 | B39: 315240 | C39: 317980 | E39: Eigentlich bin ich gerade eher, glaube ich, mir am vieren abwählen. | F39: Speaker 1 | G39: =_xlfn.XLOOKUP(A39,participants!A:A,participants!C:C) -> control_first | H39: =IF(J39 = "Chat 1", IF(P01__1[[#This Row],[group]] = "control_first", "control", "experiment"), IF(J39 = "Chat 2", IF(P01__1[[#This Row],[group]] = "control_first", "experiment", "control"), "")) | J39: Onboarding
A40: 1 | B40: 321980 | C40: 324620 | E40: Ja, four-leaf-speaking ist reine Kopfsache. | F40: Speaker 1 | G40: =_xlfn.XLOOKUP(A40,participants!A:A,participants!C:C) -> control_first | H40: =IF(J40 = "Chat 1", IF(P01__1[[#This Row],[group]] = "control_first", "control", "experiment"), IF(J40 = "Chat 2", IF(P01__1[[#This Row],[group]] = "control_first", "experiment", "control"), "")) | J40: Onboarding
A41: 1 | B41: 325660 | C41: 327440 | E41: Ja, konjugieren ist immer ein bisschen schwierig. | F41: Speaker 1 | G41: =_xlfn.XLOOKUP(A41,participants!A:A,participants!C:C) -> control_first | H41: =IF(J41 = "Chat 1", IF(P01__1[[#This Row],[group]] = "control_first", "control", "experiment"), IF(J41 = "Chat 2", IF(P01__1[[#This Row],[group]] = "control_first", "experiment", "control"), "")) | J41: Onboarding
... A66: 1 | B66: 531250 | C66: 533550 | E66: Das sollte vielleicht nicht mal beim selben rauskommen. | F66: Speaker 1 | G66: =_xlfn.XLOOKUP(A66,participants!A:A,participants!C:C) -> control_first | H66: =IF(J66 = "Chat 1", IF(P01__1[[#This Row],[group]] = "control_first", "control", "experiment"), IF(J66 = "Chat 2", IF(P01__1[[#This Row],[group]] = "control_first", "experiment", "control"), "")) | J66: Onboarding
A67: 1 | B67: 539500 | C67: 541360 | E67: Sieht lustig aus. | F67: Speaker 2 | G67: =_xlfn.XLOOKUP(A67,participants!A:A,participants!C:C) -> control_first | H67: =IF(J67 = "Chat 1", IF(P01__1[[#This Row],[group]] = "control_first", "control", "experiment"), IF(J67 = "Chat 2", IF(P01__1[[#This Row],[group]] = "control_first", "experiment", "control"), "")) | J67: Onboarding | L67: CUST_Partner
A68: 1 | B68: 542060 | C68: 544460 | E68: Du musst nach oben den Namen eingeben. | F68: Speaker 2 | G68: =_xlfn.XLOOKUP(A68,participants!A:A,participants!C:C) -> control_first | H68: =IF(J68 = "Chat 1", IF(P01__1[[#This Row],[group]] = "control_first", "control", "experiment"), IF(J68 = "Chat 2", IF(P01__1[[#This Row],[group]] = "control_first", "experiment", "control"), "")) | J68: Onboarding
A69: 1 | B69: 545200 | C69: 546640 | E69: Oh, ich muss den Namen eingeben, ja. | F69: Speaker 2 | G69: =_xlfn.XLOOKUP(A69,participants!A:A,participants!C:C) -> control_first | H69: =IF(J69 = "Chat 1", IF(P01__1[[#This Row],[group]] = "control_first", "control", "experiment"), IF(J69 = "Chat 2", IF(P01__1[[#This Row],[group]] = "control_first", "experiment", "control"), "")) | J69: Onboarding
A70: 1 | B70: 548860 | C70: 551640 | E70: Stimmt, wer nicht blind ist. | F70: Speaker 1 | G70: =_xlfn.XLOOKUP(A70,participants!A:A,participants!C:C) -> control_first | H70: =IF(J70 = "Chat 1", IF(P01__1[[#This Row],[group]] = "control_first", "control", "experiment"), IF(J70 = "Chat 2", IF(P01__1[[#This Row],[group]] = "control_first", "experiment", "control"), "")) | J70: Onboarding
A71: 1 | B71: 556650 | C71: 561750 | E71: Wenn ich mich jetzt schon einmal Frucht benannt habe, dann kriegt ihr jetzt auch einen Fruchtnamen. | F71: Speaker 1 | G71: =_xlfn.XLOOKUP(A71,participants!A:A,participants!C:C) -> control_first | H71: =IF(J71 = "Chat 1", IF(P01__1[[#This Row],[group]] = "control_first", "control", "experiment"), IF(J71 = "Chat 2", IF(P01__1[[#This Row],[group]] = "control_first", "experiment", "control"), "")) | J71: Onboarding
A72: 1 | B72: 564330 | C72: 567390 | E72: Okay, also ich vermute, das ist jetzt das erste Szenario. | F72: Speaker 1 | G72: =_xlfn.XLOOKUP(A72,participants!A:A,participants!C:C) -> control_first | H72: =IF(J72 = "Chat 1", IF(P01__1[[#This Row],[group]] = "control_first", "control", "experiment"), IF(J72 = "Chat 2", IF(P01__1[[#This Row],[group]] = "control_first", "experiment", "control"), "")) | J72: Onboarding
A73: 1 | B73: 572250 | C73: 574250 | E73: Okay, dann Generate Task. | F73: Speaker 1 | G73: =_xlfn.XLOOKUP(A73,participants!A:A,participants!C:C) -> control_first | H73: =IF(J73 = "Chat 1", IF(P01__1[[#This Row],[group]] = "control_first", "control", "experiment"), IF(J73 = "Chat 2", IF(P01__1[[#This Row],[group]] = "control_first", "experiment", "control"), "")) | J73: Onboarding
A74: 1 | B74: 574490 | C74: 576250 | E74: Klingt so, als müsste ich jetzt ein paar Aufgaben. | F74: Speaker 2 | G74: =_xlfn.XLOOKUP(A74,participants!A:A,participants!C:C) -> control_first | H74: =IF(J74 = "Chat 1", IF(P01__1[[#This Row],[group]] = "control_first", "control", "experiment"), IF(J74 = "Chat 2", IF(P01__1[[#This Row],[group]] = "control_first", "experiment", "control"), "")) | J74: Onboarding
A75: 1 | B75: 576250 | C75: 578530 | E75: Genau, bevor du weitergehst. | F75: Speaker 2 | G75: =_xlfn.XLOOKUP(A75,participants!A:A,participants!C:C) -> control_first | H75: =IF(J75 = "Chat 1", IF(P01__1[[#This Row],[group]] = "control_first", "control", "experiment"), IF(J75 = "Chat 2", IF(P01__1[[#This Row],[group]] = "control_first", "experiment", "control"), "")) | J75: Onboarding
A76: 1 | B76: 579030 | C76: 584190 | E76: Auch wichtig, jedes Szenario oder jeder Chat hat ein Limit. | F76: Speaker 2 | G76: =_xlfn.XLOOKUP(A76,participants!A:A,participants!C:C) -> control_first | H76: =IF(J76 = "Chat 1", IF(P01__1[[#This Row],[group]] = "control_first", "control", "experiment"), IF(J76 = "Chat 2", IF(P01__1[[#This Row],[group]] = "control_first", "experiment", "control"), "")) | J76: Onboarding
A77: 1 | B77: 584450 | C77: 587210 | E77: Also man kann maximal 15 Nachrichten schreiben. | F77: Speaker 2 | G77: =_xlfn.XLOOKUP(A77,participants!A:A,participants!C:C) -> control_first | H77: =IF(J77 = "Chat 1", IF(P01__1[[#This Row],[group]] = "control_first", "control", "experiment"), IF(J77 = "Chat 2", IF(P01__1[[#This Row],[group]] = "control_first", "experiment", "control"), "")) | J77: Onboarding
A78: 1 | B78: 588790 | C78: 591410 | E78: Also 15 Nachrichten jeder. | F78: Speaker 2 | G78: =_xlfn.XLOOKUP(A78,participants!A:A,participants!C:C) -> control_first | H78: =IF(J78 = "Chat 1", IF(P01__1[[#This Row],[group]] = "control_first", "control", "experiment"), IF(J78 = "Chat 2", IF(P01__1[[#This Row],[group]] = "control_first", "experiment", "control"), "")) | J78: Onboarding
...

Sheet participants
A1: ID | B1: uid | C1: Group
A2: 1 | B2: 3d3fad0c-f4e2-491f-97b3-95c71b7c6723 | C2: control_first
A3: 2 | B3: 700afe5f-e6dc-4191-9ffc-2d540d21780d | C3: experiment_first
A4: 3 | B4: 071b323f-15a1-4f26-8510-9a857540cf04 | C4: experiment_first
A5: 4 | B5: ecd6e48c-d160-4ad1-b576-772aee78a77a | C5: control_first
A6: 5 | B6: f21ef8da-e2e6-4a07-b757-2c2b8caa13df | C6: experiment_first
A7: 6 | B7: 2dbd9cc6-7d1f-4b50-9dc4-f22ba6c4aa09 | C7: control_first
A8: 7 | B8: 4ddbf84b-633f-49e1-9412-e52629d7eb1e | C8: experiment_first
A9: 8 | B9: 28ea6a5b-7ea9-41b2-851c-1317b0df0019 | C9: experiment_first
A10: 9 | B10: 05e5bd34-f2d8-4a3d-9453-e9f413cdfcf7 | C10: control_first
A11: 10 | B11: cd83ed7e-57d0-4ec5-8210-5acbbe5accae | C11: control_first
A12: 11 | B12: af32f0e9-f534-424a-9273-029dd49ac79f | C12: experiment_first
A13: 12 | B13: 71a109a5-6e81-44b3-b77f-531237e1c7d2 | C13: control_first
... A21: 20 | B21: 029df5a6-c0ca-41d9-8c3f-da05543cef44 | C21: control_first

Sheet observation_notes
A1: participant_id | B1: start | C1: end | D1: text | E1: speaker | F1: source_type | G1: main_phase | H1: sub_phase
A2: 1 | B2: 0 | C2: 0 | D2: Language level are clean | E2: Speaker 1 | F2: Observation Note | G2: Pre-Phase / General
A3: 1 | B3: 0 | C3: 0 | D3: Struggles: Which things do I select | E3: Speaker 1 | F3: Observation Note | G3: Pre-Phase / General
A4: 1 | B4: 0 | C4: 0 | D4: Makes bullet points in text field | E4: Speaker 1 | F4: Observation Note | G4: Pre-Phase / General
A5: 1 | B5: 0 | C5: 0 | D5: Nice to have the record button | E5: Speaker 1 | F5: Observation Note | G5: Warmup
A6: 1 | B6: 0 | C6: 0 | D6: Uses tutor if being lost | E6: Speaker 1 | F6: Observation Note | G6: Warmup
A7: 1 | B7: 0 | C7: 0 | D7: Was looking a bit to get out of tutor mode | E7: Speaker 1 | F7: Observation Note | G7: Warmup
A8: 1 | B8: 0 | C8: 0 | D8: Tends to ask the tutor as a quick fix for uncertain situations | E8: Speaker 1 | F8: Observation Note | G8: Warmup
A9: 1 | B9: 0 | C9: 0 | D9: Has the impression that AI is bad at referencing past messages | E9: Speaker 1 | F9: Observation Note | G9: Warmup
A10: 1 | B10: 0 | C10: 0 | D10: Tutor references the wrong message P. tried to just copy and paste the message | E10: Speaker 1 | F10: Observation Note | G10: Warmup
A11: 1 | B11: 0 | C11: 0 | D11: Likes the tutor, also the format | E11: Speaker 1 | F11: Observation Note | G11: Warmup
A12: 1 | B12: 0 | C12: 0 | D12: Uses tutor very intensely | E12: Speaker 1 | F12: Observation Note | G12: Warmup
A13: 1 | B13: 0 | C13: 0 | D13: Asks questions about pronunciation, which the ai can’t answer in audio | E13: Speaker 1 | F13: Observation Note | G13: Warmup
... A15: 1 | B15: 0 | C15: 0 | D15: AI misunderstood P. but he thought, that he mispronounced it | E15: Speaker 1 | F15: Observation Note | G15: Warmup
A16: 1 | B16: 0 | C16: 0 | D16: Really likes the hint function | E16: Speaker 1 | F16: Observation Note | G16: Warmup | H16: Partner explained something in Spanish instead of English
A17: 1 | B17: 0 | C17: 0 | D17: Does not understand the red highlight, what the mistake was | E17: Speaker 1 | F17: Observation Note | G17: Warmup | H17: Partner explained something in Spanish instead of English
A18: 1 | B18: 0 | C18: 0 | D18: Really likes that its spoken audio and that there are explanations in the partner message | E18: Speaker 1 | F18: Observation Note | G18: Warmup | H18: Partner explained something in Spanish instead of English
A19: 1 | B19: 0 | C19: 0 | D19: Tried to do it intuitively | E19: Speaker 1 | F19: Observation Note | G19: Warmup | H19: Think Aloud
A20: 1 | B20: 0 | C20: 0 | D20: Overread that he has to do the task | E20: Speaker 1 | F20: Observation Note | G20: Warmup | H20: Think Aloud
A21: 1 | B21: 0 | C21: 0 | D21: Doesn’t know how fast he could do it without the hint | E21: Speaker 1 | F21: Observation Note | G21: Warmup | H21: Think Aloud
A22: 1 | B22: 0 | C22: 0 | D22: When realizing there are hints, switched from tutor to using hints Were really good | E22: Speaker 1 | F22: Observation Note | G22: Warmup | H22: Think Aloud
A23: 1 | B23: 0 | C23: 0 | D23: Got into it after a few messages | E23: Speaker 1 | F23: Observation Note | G23: Warmup | H23: Think Aloud
A24: 1 | B24: 0 | C24: 0 | D24: Felt good: Corrections were woven into the responses, felt like he was learning with a partner | E24: Speaker 1 | F24: Observation Note | G24: Warmup | H24: Think Aloud
A25: 1 | B25: 0 | C25: 0 | D25: Tried to give it his own touch | E25: Speaker 1 | F25: Observation Note | G25: Warmup | H25: Think Aloud
A26: 1 | B26: 0 | C26: 0 | D26: Thought app crashed because of loading animation | E26: Speaker 1 | F26: Observation Note | G26: Warmup | H26: Summary
A27: 1 | B27: 0 | C27: 0 | D27: Like the cite | E27: Speaker 1 | F27: Observation Note | G27: Warmup | H27: Summary
... A33: 1 | B33: 0 | C33: 0 | D33: But reading the updates feels a bit frustrating to see, because it lists so many weak points | E33: Speaker 1 | F33: Observation Note | G33: Warmup | H33: Summary
A34: 1 | B34: 0 | C34: 0 | D34: Wanted to check the hint, but oversaw that now it’s the solution | E34: Speaker 1 | F34: Observation Note | G34: Chat 1
A35: 1 | B35: 0 | C35: 0 | D35: Tends to use the hint when unsure | E35: Speaker 1 | F35: Observation Note | G35: Chat 1
A36: 1 | B36: 0 | C36: 0 | D36: Ai skipped one task, then the AI continued but was confused | E36: Speaker 1 | F36: Observation Note | G36: Chat 1
A37: 1 | B37: 0 | C37: 0 | D37: Tends to use only the hint/solution without adding extra content | E37: Speaker 1 | F37: Observation Note | G37: Chat 1
A38: 1 | B38: 0 | C38: 0 | D38: Reads the summary very carefully | E38: Speaker 1 | F38: Observation Note | G38: Chat 1 | H38: Summary
A39: 1 | B39: 0 | C39: 0 | D39: Connection issue in the beginning of the convo | E39: Speaker 1 | F39: Observation Note | G39: Chat 2
A40: 1 | B40: 0 | C40: 0 | D40: Got a personalized explanation | E40: Speaker 1 | F40: Observation Note | G40: Chat 2 | H40: Partner made a joke, P. had to laugh
A41: 1 | B41: 0 | C41: 0 | D41: Reconnection error | E41: Speaker 1 | F41: Observation Note | G41: Chat 2 | H41: Partner made a joke, P. had to laugh
A42: 1 | B42: 0 | C42: 0 | D42: For abblino: | E42: Speaker 1 | F42: Observation Note | G42: Chat 2 | H42: Partner made a joke, P. had to laugh
A43: 1 | B43: 0 | C43: 0 | D43: Always have pronunciation option for all messages | E43: Speaker 1 | F43: Observation Note | G43: Chat 2 | H43: Partner made a joke, P. had to laugh
A44: 1 | B44: 0 | C44: 0 | D44: Hint feature | E44: Speaker 1 | F44: Observation Note | G44: Chat 2 | H44: Partner made a joke, P. had to laugh
A45: 1 | B45: 0 | C45: 0 | D45: Offer a translation of the messages | E45: Speaker 1 | F45: Observation Note | G45: Chat 2 | H45: Partner made a joke, P. had to laugh
A46: 2 | B46: 0 | C46: 0 | D46: Likes the design | E46: Speaker 1 | F46: Observation Note | G46: Onboarding
...

Sheet P20
A1: start | B1: end | C1: text | D1: speaker
A2: 1160 | B2: 1800 | C2: Hallo. | D2: Speaker 2
A3: 2240 | B3: 2520 | C3: Okay. | D3: Speaker 1
A4: 2880 | B4: 3560 | C4: Okay, super. | D4: Speaker 1
A5: 3680 | B5: 4160 | C5: Es klingt auf. | D5: Speaker 1
A6: 4620 | B6: 4820 | C6: Genau. | D6: Speaker 1
A7: 4980 | B7: 14960 | C7: Erstmal, bevor wir anfangen, danke, dass du dir die Zeit nimmst, heute teilzunehmen und das Interview dauert so 45 bis 60 Minuten. | D7: Speaker 1
A8: 16480 | B8: 23300 | C8: Das Interview wird aufgezeichnet und ist dann später zu transkribieren und die Aufzeichnung wird dann nach der Transkription gelöscht. | D8: Speaker 1
A9: 23840 | B9: 31479 | C9: Du kannst auch jederzeit das Interview stoppen oder deine Einverständniserklärung entziehen, ohne irgendwelche Gründe zu nennen oder Nachteile zu empfangen. | D9: Speaker 1
A10: 32280 | B10: 34740 | C10: Deswegen einmal die Frage, ob du damit einverstanden bist. | D10: Speaker 1
A11: 35340 | B11: 35500 | C11: Ja. | D11: Speaker 1
A12: 35940 | B12: 36420 | C12: Okay, super. | D12: Speaker 1
A13: 37180 | B13: 38720 | C13: Dann nochmal kurz zur Struktur. | D13: Speaker 1
... A748: 4081180 | B748: 4083000 | C748: Dann beende ich einmal die Aufnahme. | D748: Speaker 1

Sheet P19
A1: start | B1: end | C1: text | D1: speaker
A2: 0 | B2: 3390 | C2: Gesamter Bildschirm, Bildschirm 1. | D2: Speaker 1
A3: 8920 | B3: 10240 | C3: Okay, perfekt. | D3: Speaker 1
A4: 12000 | B4: 15720 | C4: Genau, ich habe in den Chats die beiden Links geschickt. | D4: Speaker 1
A5: 16020 | B5: 18280 | C5: Einmal für die App. | D5: Speaker 1
A6: 20500 | B6: 21340 | C6: Wo sehen wir denn den Chat? | D6: Speaker 1
A7: 22940 | B7: 24520 | C7: Ich glaube, der ist da. | D7: Speaker 1
A8: 25380 | B8: 26340 | C8: Wo ist denn der bei dir? | D8: Speaker 1
A9: 27840 | B9: 29940 | C9: Bei weiterer Option vielleicht. | D9: Speaker 1
A10: 30000 | B10: 30760 | C10: Ah ne, da unten. | D10: Speaker 1
A11: 35130 | B11: 37750 | C11: Genau, der untere ist der Fragebogen. | D11: Speaker 1
A12: 38410 | B12: 40290 | C12: Dann sage ich dir aber nochmal Bescheid. | D12: Speaker 1
A13: 40810 | B13: 41270 | C13: Erste, oder? | D13: Speaker 1
... A1071: 5654570 | B1071: 5654710 | C1071: Vielen Dank. | D1071: Speaker 1

Sheet P18
A1: start | B1: end | C1: text | D1: speaker
A2: 880 | B2: 6560 | C2: Bevor du weitermachst, ich hab noch mal so ein kleines Skript, das würde ich einmal durchgehen, und dann... | D2: Speaker 2
A3: 8120 | B3: 8480 | C3: Moment. | D3: Speaker 2
A4: 11530 | B4: 14970 | C4: Jetzt wollte ich nur gerade mal gucken, wie ich das hier anders anordnen kann. | D4: Speaker 2
A5: 34590 | B5: 34690 | C5: Okay. | D5: Speaker 2
A6: 35550 | B6: 36450 | C6: Machst du so wahrscheinlich? | D6: Speaker 2
A7: 37090 | B7: 37930 | C7: Ja, perfekt, okay. | D7: Speaker 2
A8: 38810 | B8: 39710 | C8: Ähm, okay, super. | D8: Speaker 2
A9: 40490 | B9: 40850 | C9: Dann... | D9: Speaker 2
A10: 40850 | B10: 43310 | C10: Genau, ich hab hier so ein kleines Skript, ich schreib's so nebenbei einfach mit. | D10: Speaker 2
A11: 44190 | B11: 46950 | C11: Äh, aber erst mal danke dir nochmal, dass du dir die Zeit nimmst. | D11: Speaker 2
A12: 47470 | B12: 50050 | C12: Und die Studie dauert so 45 bis 60 Minuten. | D12: Speaker 2
A13: 50910 | B13: 51390 | C13: Okay. | D13: Speaker 2
... A761: 5545360 | B761: 5546840 | C761: Dann beende ich einmal die Aufnahme. | D761: Speaker 2

Sheet P17
A1: start | B1: end | C1: text | D1: speaker
A2: 710 | B2: 1830 | C2: Genau, okay. | D2: Speaker 2
A3: 2330 | B3: 10170 | C3: Genau, dann nochmal danke dir, dass du dir heute die Zeit nimmst und ich habe hier noch so ein kleines Skript, also nicht, dass du dich wunderst. | D3: Speaker 2
A4: 10270 | B4: 11490 | C4: Ich gehe das einmal durch. | D4: Speaker 2
A5: 12190 | B5: 29830 | C5: Also die Studie dauert so 45 bis 60 Minuten und das Interview wird aufgezeichnet, um das dann später zu transkribieren und die Aufnahme wird dann nach der Transkription gelöscht und du kannst auch jederzeit das Interview anhalten oder deine Einverständnis entziehen, ohne irgendwelche Gründe zu nennen oder Nachteile zu erfahren. | D5: Speaker 2
A6: 30430 | B6: 32890 | C6: Deswegen einmal die Frage, ob du damit einverstanden bist. | D6: Speaker 2
A7: 33750 | B7: 33870 | C7: Ja. | D7: Speaker 1
A8: 34610 | B8: 35110 | C8: Okay, super. | D8: Speaker 2
A9: 35670 | B9: 37210 | C9: Genau, dann nochmal kurz zur Struktur. | D9: Speaker 2
A10: 37910 | B10: 48850 | C10: Also gleich, wenn du in der App bist, hast du erstmal so ein kleines Onboarding, wo du dann zum Beispiel dein Sprachlevel angibst und so weiter und danach hast du dann drei Konversationen. | D10: Speaker 2
A11: 48850 | B11: 51850 | C11: Die erste Konversation, da wird eigentlich noch | D11: Speaker 2
A12: 51850 | B12: 55470 | C12: nichts gemessen und es geht erstmal nur darum, dass du so ein bisschen dich mit | D12: Speaker 2
A13: 55470 | B13: 58410 | C13: dem System vertraut machen kannst und so ein bisschen gucken kannst, wie das | D13: Speaker 2
... A482: 3602290 | B482: 3603370 | C482: Kann er auch Spanisch? | D482: Speaker 1

Sheet P16
A1: start | B1: end | C1: text | D1: speaker
A2: 720 | B2: 1460 | C2: Aufnahmebeginn, genau. | D2: Speaker 2
A3: 2560 | B3: 8480 | C3: Und ich habe hier so ein kleines Interviewleitfaden, also nicht, dass du dich wunderst, wenn ich mal hier so ein bisschen schreibe. | D3: Speaker 2
A4: 10360 | B4: 14000 | C4: Genau, dann also nochmal danke dir, dass du dir heute die Zeit nimmst. | D4: Speaker 2
A5: 14860 | B5: 15000 | C5: Sehr gerne. | D5: Speaker 2
A6: 15000 | B6: 18480 | C6: Und die Studie dauert so ungefähr 45 bis 60 Minuten. | D6: Speaker 2
A7: 19220 | B7: 32780 | C7: Das Interview wird aufgezeichnet, um das dann später zu transkribieren und die Audio wird dann nach der Transkription gelöscht und du kannst auch jederzeit das Interview anhalten oder deine Einverständnis entziehen, ohne Gründe zu nennen oder irgendwelche Nachteile zu bekommen. | D7: Speaker 2
A8: 33260 | B8: 35520 | C8: Deswegen einmal die Frage, ob du damit einverstanden bist. | D8: Speaker 2
A9: 35760 | B9: 36020 | C9: Klar. | D9: Speaker 1
A10: 36900 | B10: 39160 | C10: Bist du denn jetzt hier live dabei, wenn ich das mache? | D10: Speaker 1
A11: 39800 | B11: 40860 | C11: Genau, genau, ich bin live dabei. | D11: Speaker 2
A12: 42580 | B12: 44260 | C12: Warum hast du das auf Englisch? | D12: Speaker 1
A13: 44460 | B13: 45500 | C13: How should we call you? | D13: Speaker 1
... A715: 4204330 | B715: 4206190 | C715: Dann beende ich einmal die Aufnahme. | D715: Speaker 2

Sheet P15
A1: start | B1: end | C1: text | D1: speaker
A2: 840 | B2: 2960 | C2: Genau, okay, super. | D2: Speaker 1
A3: 3340 | B3: 5220 | C3: Dann danke dir nochmal, dass du dir die Zeit nimmst. | D3: Speaker 1
A4: 5380 | B4: 14840 | C4: Die Studie dauert so 45 bis 60 Minuten und das Interview wird aufgezeichnet, um das dann später zu transkribieren und die Aufnahme wird auch nach der Transkription gelöscht. | D4: Speaker 1
A5: 15140 | B5: 21800 | C5: Du kannst jederzeit das Interview anhalten oder deine Einwilligung entziehen, ohne irgendwelche Gründe zu nennen oder Nachteile zu erfahren. | D5: Speaker 1
A6: 22940 | B6: 25160 | C6: Deswegen einmal die Frage, ob du damit einverstanden bist. | D6: Speaker 1
A7: 26180 | B7: 27240 | C7: Ich bin einverstanden. | D7: Speaker 1
A8: 27740 | B8: 28600 | C8: Okay, perfekt. | D8: Speaker 1
A9: 29360 | B9: 30860 | C9: Genau, dann nochmal kurz zum Aufbau. | D9: Speaker 1
A10: 31000 | B10: 38280 | C10: Also du hast jetzt gleich, wenn du auf Start Study klickst, ein kleines Onboarding, wo du so ein paar Daten über dich angibst. | D10: Speaker 1
A11: 38280 | B11: 41300 | C11: Dann hast du drei Konversationen. | D11: Speaker 1
A12: 41400 | B12: 46700 | C12: Einmal diese Warm-up-Konversation und dann jeweils eine oder zwei weitere Konversationen. | D12: Speaker 1
A13: 46820 | B13: 49020 | C13: Und am Ende stelle ich dann noch ein paar Fragen. | D13: Speaker 1
... A476: 4475710 | B476: 4479830 | C476: Dann danke dir für deine Teilnahme und dann beende ich einmal die Aufnahme. | D476: Speaker 1

Sheet P14
A1: start | B1: end | C1: text | D1: speaker
A2: 140 | B2: 24220 | C2: Genau, dann nochmal danke dir, dass du dir die Zeit nimmst und die Studie dauert so ungefähr 45 bis 60 Minuten und das Interview wird aufgezeichnet, um das dann später zu transkribieren und die Aufnahme wird dann nach der Transkription gelöscht und du kannst auch jederzeit das Interview anhalten oder deine Einverständnis entziehen, ohne Gründe zu nennen oder irgendwelche Nachteile zu erfahren. | D2: Speaker 1
A3: 24720 | B3: 27240 | C3: Deswegen einmal die Frage, ob du damit einverstanden bist? | D3: Speaker 1
A4: 27240 | B4: 28480 | C4: Ja. | D4: Speaker 1
A5: 57240 | B5: 78440 | C5: Nee. | D5: Speaker 1
A6: 78440 | B6: 79980 | C6: Okay, kein Problem. | D6: Speaker 1
A7: 80360 | B7: 94000 | C7: Genau, also das muss man sich so vorstellen, eigentlich wie so der Kommentator deiner Gedanken, also dass du quasi die Gedanken, die du während der Interaktion hast, laut aussprechen kannst. | D7: Speaker 1
A8: 95200 | B8: 108160 | C8: Also das hilft dann zum Beispiel mir dabei herauszufinden, wo vielleicht Punkte in der App sind, die noch nicht so gut funktionieren oder wo dann die Nutzer irritiert sind oder was anderes erwarten. | D8: Speaker 1
A9: 109500 | B9: 113720 | C9: Und genau, du kannst aber … | D9: Speaker 1
A10: 113720 | B10: 116360 | C10: Also ich soll eigentlich meine Gedanken laut aussprechen? | D10: Speaker 2
A11: 116360 | B11: 117500 | C11: Genau, genau. | D11: Speaker 1
A12: 118700 | B12: 127639 | C12: Nur bei der ersten Konversation habe ich auch öfter gemerkt, dass manchmal ist das ein bisschen überfordernd, dann irgendwie gleichzeitig Spanisch und dann auf Deutsch irgendwie die Gedanken sagen. | D12: Speaker 1
A13: 128120 | B13: 135900 | C13: Deswegen, wenn du merkst, das ist dann doch irgendwie zu viel, ist das gar kein Problem, dann können wir das so im Nachhinein machen. | D13: Speaker 1
... A406: 4286880 | B406: 4289320 | C406: Und dann beende ich einmal die Aufnahme. | D406: Speaker 1

Sheet P13
A1: start | B1: end | C1: text | D1: speaker
A2: 1900 | B2: 9000 | C2: Also nochmal danke für deine Teilnahme und die Studie dauert so ungefähr 45 bis 60 Minuten. | D2: Speaker 1
A3: 10380 | B3: 18640 | C3: Das Interview wird aufgezeichnet, um das dann später zu transkribieren und die Aufnahme wird dann nach der Transkription gelöscht. | D3: Speaker 1
A4: 18820 | B4: 26660 | C4: Und du kannst auch jederzeit das Interview anhalten oder deine Einverständniserklärung entziehen, ohne irgendwelche Gründe zu nennen oder Nachteile zu erfahren. | D4: Speaker 1
A5: 26660 | B5: 29720 | C5: Deswegen einmal die Frage, ob du damit einverstanden bist. | D5: Speaker 1
A6: 30760 | B6: 32380 | C6: Ja, ich bin damit einverstanden. | D6: Speaker 1
A7: 33140 | B7: 33860 | C7: Okay, perfekt. | D7: Speaker 1
A8: 34580 | B8: 36480 | C8: Genau, dann nochmal zur Struktur. | D8: Speaker 1
A9: 36700 | B9: 41660 | C9: Also du hast gleich so ein kleines Onboarding, wo du durchgehst und dann danach hast du drei Konversationen. | D9: Speaker 1
A10: 42340 | B10: 44640 | C10: Die erste ist so eine Art Warm-up-Konversation. | D10: Speaker 1
A11: 44780 | B11: 50660 | C11: Das heißt, da kannst du quasi ganz entspannt erstmal die App ausprobieren, dich so ein bisschen zurechtfinden. | D11: Speaker 1
A12: 52020 | B12: 55660 | C12: Und dann quasi zwei weitere Konversationen. | D12: Speaker 1
A13: 56520 | B13: 58260 | C13: Und danach würde ich noch ein paar Fragen stellen. | D13: Speaker 1
... A860: 5782870 | B860: 5786970 | C860: Dann danke dir für deine Teilnahme und dann beende ich einmal die Aufnahme. | D860: Speaker 1

Sheet P12
A1: start | B1: end | C1: text | D1: speaker
A2: 970 | B2: 7710 | C2: Und dann öffne ich noch einmal mein Skript, Moment. | D2: Speaker 1
A3: 9960 | B3: 19500 | C3: Muss ich jetzt auf diese andere App, also auf diese Conversation Language Learning, also fangen wir erst damit an und dann auf Next, also weiterklicken, oder? | D3: Speaker 1
A4: 20240 | B4: 25180 | C4: Die ist noch nicht relevant, also da musst du noch nichts machen. | D4: Speaker 1
A5: 25560 | B5: 29640 | C5: Das ist nur ein Fragebogen, weil du hast ja drei Konversationen. | D5: Speaker 1
A6: 29640 | B6: 34420 | C6: Nach der zweiten und dritten würde ich dich bitten, dann einmal den Fragebogen auszufüllen. | D6: Speaker 1
A7: 38940 | B7: 40820 | C7: Okay, also hiermit machen wir jetzt erst mal weiter. | D7: Speaker 1
A8: 41920 | B8: 47960 | C8: Genau, also mit der, ich weiß gerade nicht auf welchen, bist du auf der App drauf? | D8: Speaker 1
A9: 48860 | B9: 49520 | C9: Ja, perfekt. | D9: Speaker 1
A10: 50380 | B10: 50640 | C10: Okay. | D10: Speaker 1
A11: 51500 | B11: 52300 | C11: Ja, ja. | D11: Speaker 1
A12: 53380 | B12: 53940 | C12: Okay, super. | D12: Speaker 1
A13: 54540 | B13: 57840 | C13: Genau, dann danke dir nochmal, dass du hier teilnimmst. | D13: Speaker 1
... A472: 3909010 | B472: 3912470 | C472: Dann danke dir für deine Teilnahme und ich beende einmal die Aufnahme. | D472: Speaker 1

Sheet P11
A1: start | B1: end | C1: text | D1: speaker
A2: 0 | B2: 18720 | C2: Okay, dann nochmal danke dir, dass du dir die Zeit genommen hast und das Interview oder die Studie dauert so 45 bis 60 Minuten und das Interview wird aufgezeichnet, um das dann später zu transkribieren und die Audio wird dann nach der Transkription gelöfft. | D2: Speaker 2
A3: 18800 | B3: 26500 | C3: Du kannst auch jederzeit das Interview anhalten oder deine Einverständniserklärung entziehen, ohne Gründe zu nennen oder irgendwelche Nachteile zu bekommen. | D3: Speaker 2
A4: 27080 | B4: 29560 | C4: Deswegen einmal die Frage, ob du damit einverstanden bist. | D4: Speaker 2
A5: 30360 | B5: 31159 | C5: Ja, bin ich. | D5: Speaker 2
A6: 31980 | B6: 32640 | C6: Okay, perfekt. | D6: Speaker 2
A7: 33120 | B7: 34560 | C7: Genau, dann nochmal kurz zur Struktur. | D7: Speaker 2
A8: 34840 | B8: 40720 | C8: Also, du bist ja jetzt schon auf der App und du hast jetzt gleich erstmal so ein kleines Onboarding. | D8: Speaker 2
A9: 41520 | B9: 44760 | C9: Dann hast du drei Konversationen. | D9: Speaker 2
A10: 45100 | B10: 54240 | C10: Die erste Konversation ist quasi eine Warm-up-Konversation, das heißt, da kannst du dich erstmal mit dem ganzen System vertraut machen und das ist quasi ganz entspannt. | D10: Speaker 2
A11: 54860 | B11: 64379 | C11: Und dann jeweils noch zwei weitere Konversationen und am Ende dann nochmal ein paar tiefergehende Fragen. | D11: Speaker 2
A12: 67500 | B12: 76920 | C12: Und nach der zweiten und dritten Konversation würde ich dich dann bitten, den Fragebogen auszufüllen für die beiden Konversationen, aber da sage ich dir dann noch Bescheid. | D12: Speaker 2
A13: 78400 | B13: 86620 | C13: Genau, und ich würde bei der Warm-up-Konversation die Think-Aloud-Methode anwenden. | D13: Speaker 2
... A833: 4696550 | B833: 4702690 | C833: Okay, dann danke dir für deine Teilnahme und dann beende ich einmal die Aufnahme. | D833: Speaker 2

Sheet P10
A1: start | B1: end | C1: text | D1: speaker
A2: 1440 | B2: 3840 | C2: Okay, perfekt. | D2: Speaker 1
A3: 3960 | B3: 10560 | C3: Genau, dann nochmal danke dir, dass du dir die Zeit nimmst heute und die Nutzerstudie dauert so 45 bis 60 Minuten. | D3: Speaker 1
A4: 11440 | B4: 26540 | C4: Das Interview wird aufgezeichnet, um das dann später zu transkribieren und die Audio wird dann nach der Transkription gelöscht und du kannst auch jederzeit das Interview anhalten oder deine Einwilligungserklärung entziehen, ohne Gründe zu nennen oder irgendwelche Nachteile zu erfahren. | D4: Speaker 1
